<mujoco>

  <worldbody>
    <light pos="0 0 1.5" dir="0 0 -1" directional="true"/>
    <geom name="floor" size="0 0 0.05" type="plane" material="groundplane" friction=".5 0.005 0.001"  priority="2" condim="4"/>
  </worldbody>


  <worldbody>
    <body name="ball" pos="0 0 0.05">
        <geom name="gball_0" type="sphere" size="0.02" mass="1." material="BallMat" friction=".5 0.005 0.001 " condim="4"  />
        <site name="sensor_ball" />
        <joint name="joint_x" type="slide" pos="0 0 0" axis="1 0 0"/>
        <joint name="joint_y" type="slide" pos="0 0 0" axis="0 1 0"/>
        <!-- <joint name="joint_z" type="slide" pos="0 0 0" axis="0 0 1"/> -->
    </body>
  </worldbody>

  <actuator>
    <motor name="actuator_x" joint="joint_x" gear="1"/>
    <motor name="actuator_y" joint="joint_y" gear="1"/>
  </actuator>

    <asset>
    <!-- Materials for visualization -->
        <material name="MatPlane" rgba="0.8 0.9 0.8 1"/>
        <material name="BallMat" rgba="0.2 0.2 0.8 1"/>

        <texture type="skybox" builtin="gradient" rgb1="0.3 0.5 0.7" rgb2="0 0 0" width="512" height="3072"/>
        <texture type="2d" name="groundplane" builtin="checker" mark="edge" rgb1="0.2 0.3 0.4" rgb2="0.1 0.2 0.3"
        markrgb="0.8 0.8 0.8" width="300" height="300"/>
        <material name="groundplane" texture="groundplane" texuniform="true" texrepeat="5 5" reflectance="0.2"/>
    </asset>

    <sensor>
        <velocimeter name="sensor_ball" site="sensor_ball"/>
    </sensor>


</mujoco>